<?xml version="1.0" encoding="utf-8"?><testsuites><testsuite name="pytest" errors="1" failures="1" skipped="0" tests="7" time="0.937" timestamp="2022-06-14T23:40:21.636569" hostname="eduardo"><testcase classname="test_api.ApiTest" name="test_when_I_call_health_check_should_be_success" file="test_api.py" line="10" time="0.035" /><testcase classname="test_api.ApiTest" name="test_when_I_call_metrics_path_should_be_success" file="test_api.py" line="19" time="0.005" /><testcase classname="test_api.ApiTest" name="test_when_I_call_root_path_should_be_success" file="test_api.py" line="15" time="0.007" /><testcase classname="database.test_connection.ConnectionTest" name="test_when_I_call_get_connection_string_should_be_success" file="database/test_connection.py" line="15" time="0.003" /><testcase classname="routers.test_users.UsersRouterTest" name="test_when_I_call_create_user_should_be_success" file="routers/test_users.py" line="32" time="0.004"><failure message="AssertionError: None != 1">self = &lt;test_users.UsersRouterTest testMethod=test_when_I_call_create_user_should_be_success&gt;, get_db_mock = &lt;MagicMock name='get_db()' id='140441877508400'&gt;

    def test_when_I_call_create_user_should_be_success(self, get_db_mock):
        get_db_mock = get_db_mock.return_value
        get_db_mock.add = MagicMock(return_value=self.model_user_response)
        response = create_user(self.model_user_request, get_db_mock)
        print(response)
&gt;       self.assertEqual(response.id, self.model_user_response.id)
E       AssertionError: None != 1

tests/routers/test_users.py:38: AssertionError</failure></testcase><testcase classname="routers.test_users.UsersRouterTest" name="test_when_I_call_get_all_users_should_be_success" file="routers/test_users.py" line="24" time="0.002" /><testcase classname="pytest" name="internal" time="0.000"><error message="internal error">Traceback (most recent call last):
  File "/home/eduardo/.local/share/virtualenvs/cybersecurity-fiap-uFibwHRG/lib/python3.8/site-packages/_pytest/main.py", line 268, in wrap_session
    session.exitstatus = doit(config, session) or 0
  File "/home/eduardo/.local/share/virtualenvs/cybersecurity-fiap-uFibwHRG/lib/python3.8/site-packages/_pytest/main.py", line 322, in _main
    config.hook.pytest_runtestloop(session=session)
  File "/home/eduardo/.local/share/virtualenvs/cybersecurity-fiap-uFibwHRG/lib/python3.8/site-packages/pluggy/_hooks.py", line 265, in __call__
    return self._hookexec(self.name, self.get_hookimpls(), kwargs, firstresult)
  File "/home/eduardo/.local/share/virtualenvs/cybersecurity-fiap-uFibwHRG/lib/python3.8/site-packages/pluggy/_manager.py", line 80, in _hookexec
    return self._inner_hookexec(hook_name, methods, kwargs, firstresult)
  File "/home/eduardo/.local/share/virtualenvs/cybersecurity-fiap-uFibwHRG/lib/python3.8/site-packages/pluggy/_callers.py", line 55, in _multicall
    gen.send(outcome)
  File "/home/eduardo/.local/share/virtualenvs/cybersecurity-fiap-uFibwHRG/lib/python3.8/site-packages/pytest_cov/plugin.py", line 294, in pytest_runtestloop
    self.cov_controller.finish()
  File "/home/eduardo/.local/share/virtualenvs/cybersecurity-fiap-uFibwHRG/lib/python3.8/site-packages/pytest_cov/engine.py", line 44, in ensure_topdir_wrapper
    return meth(self, *args, **kwargs)
  File "/home/eduardo/.local/share/virtualenvs/cybersecurity-fiap-uFibwHRG/lib/python3.8/site-packages/pytest_cov/engine.py", line 189, in summary
    total = self.cov.html_report(ignore_errors=True, directory=output)
  File "/home/eduardo/.local/share/virtualenvs/cybersecurity-fiap-uFibwHRG/lib/python3.8/site-packages/coverage/control.py", line 1029, in html_report
    ret = reporter.report(morfs)
  File "/home/eduardo/.local/share/virtualenvs/cybersecurity-fiap-uFibwHRG/lib/python3.8/site-packages/coverage/html.py", line 239, in report
    self.write_html_file(ftr, prev_html, next_html)
  File "/home/eduardo/.local/share/virtualenvs/cybersecurity-fiap-uFibwHRG/lib/python3.8/site-packages/coverage/html.py", line 363, in write_html_file
    write_html(html_path, html)
  File "/home/eduardo/.local/share/virtualenvs/cybersecurity-fiap-uFibwHRG/lib/python3.8/site-packages/coverage/html.py", line 43, in write_html
    with open(fname, "wb") as fout:
PermissionError: [Errno 13] Permission denied: 'htmlcov/d_5f5a17c013354698_api_py.html'</error></testcase></testsuite></testsuites>